Workbook

Sheet 1. Executive Summary
A1: INDONESIA KNUCKLE BOOM CRANE MARKET — EXECUTIVE SUMMARY (2023–2026 YTD)
B3: KEY METRICS
B4: Metric | C4: 2023 | D4: 2024 | E4: 2025 | F4: 2026 YTD (s/d Aug)
B5: Transactions | C5: =COUNTIF(Data!$D$2:$D$765,2023) -> 267 | D5: =COUNTIF(Data!$D$2:$D$765,2024) -> 191 | E5: =COUNTIF(Data!$D$2:$D$765,2025) -> 227 | F5: =COUNTIF(Data!$D$2:$D$765,2026) -> 79
B6: Import Value (USD) | C6: =SUMIF(Data!$D$2:$D$765,2023,Data!$F$2:$F$765) -> 6401717.4 | D6: =SUMIF(Data!$D$2:$D$765,2024,Data!$F$2:$F$765) -> 6108371.8 | E6: =SUMIF(Data!$D$2:$D$765,2025,Data!$F$2:$F$765) -> 7039257.3 | F6: =SUMIF(Data!$D$2:$D$765,2026,Data!$F$2:$F$765) -> 1524050.4
B7: Avg Price / Unit (USD) | C7: =IFERROR(C6/C5,0) -> 23976.47 | D7: =IFERROR(D6/D5,0) -> 31981.004 | E7: =IFERROR(E6/E5,0) -> 31009.944 | F7: =IFERROR(F6/F5,0) -> 19291.777
B9: 4-YEAR TOTAL | C9: =SUM(C5:F5) -> 764 | D9: =SUM(C6:F6) -> 21073397
B11: KATEGORI MAX LIFTING MOMENT — APA ARTINYA
B12: Kategori | C12: Rentang Max Lifting Moment | D12: Kebutuhan Rear Outrigger | E12: Rentang GVW Truk
B13: Light | C13: ≤ 8 tm | D13: Tidak perlu rear outrigger | E13: 2 – 10 ton
B14: Small | C14: > 8 – 25 tm | D14: Tidak perlu rear outrigger | E14: 10 – 19 ton
B15: Medium | C15: > 25 – 45 tm | D15: Perlu rear outrigger | E15: 19 – 42 ton
B16: Heavy | C16: > 45 tm | D16: Perlu rear outrigger + minimum GVW 42 ton | E16: 42 ton
A17: Batas kategori bersifat kumulatif: nilai tepat di batas atas masuk kategori tersebut (mis. 8 tm = Light, 25 tm = Small, 45 tm = Medium).
B19: TOP INSIGHTS
B20: 1. MARKET LEADERSHIP — SANY PALFINGER memimpin volume dengan 302 transaksi (40% unit share) dari 764 transaksi.
B21: 2. VALUE LEADERSHIP — PALFINGER memegang value share terbesar (USD 6.3 juta, 30%).
B22: 3. KATEGORI DOMINAN — Light 248 txn (32%), Small 223 txn (29%), Medium 218 txn (29%), Heavy 75 txn (10%). Terbesar: Light.
B23: 4. PAIRING TRUK — Kebutuhan truk paling banyak di kelas GVW 10 ton (233 unit crane, 30%), berdasarkan kurva rekomendasi Ferrari.
B24: 5. MODEL TERLARIS — SANY PALFINGER SPK8500 (48 txn).
B25: 6. POSISI TSP — Hyva, Amco Veba, dan Ferrari: 171 txn (22% unit), USD 4.6 juta (22% value).
B26: 7. KUALITAS DATA — 764 dari 764 baris (100%) punya angka Max Lifting Moment terverifikasi; seluruh baris GENERIC (tanpa kode model) telah dihapus.
B28: Kategori: Light 1–6 tm, Small 7–15 tm, Medium 16–45 tm, Heavy >45 tm — dari Max Lifting Moment dibulatkan. GVW truk mengikuti kurva rekomendasi F.lli Ferrari (sheet 10).

Sheet 2. Market Structure
A1: MARKET STRUCTURE — BRAND SHARE BY UNITS & VALUE
A3: Brand | B3: 2023 | C3: 2024 | D3: 2025 | E3: 2026 | F3: Total Txn | G3: Share (Units) | H3: Value (USD) | I3: Share (Value)
A4: SANY PALFINGER | B4: =COUNTIFS(Data!$A$2:$A$765,$A4,Data!$D$2:$D$765,2023) -> 81 | C4: =COUNTIFS(Data!$A$2:$A$765,$A4,Data!$D$2:$D$765,2024) -> 74 | D4: =COUNTIFS(Data!$A$2:$A$765,$A4,Data!$D$2:$D$765,2025) -> 92 | E4: =COUNTIFS(Data!$A$2:$A$765,$A4,Data!$D$2:$D$765,2026) -> 55 | F4: =SUM(B4:E4) -> 302 | G4: =F4/$F$16 -> 0.39528796 | H4: =SUMIF(Data!$A$2:$A$765,$A4,Data!$F$2:$F$765) -> 5341594.6 | I4: =H4/$H$16 -> 0.25347573
A5: PALFINGER | B5: =COUNTIFS(Data!$A$2:$A$765,$A5,Data!$D$2:$D$765,2023) -> 35 | C5: =COUNTIFS(Data!$A$2:$A$765,$A5,Data!$D$2:$D$765,2024) -> 59 | D5: =COUNTIFS(Data!$A$2:$A$765,$A5,Data!$D$2:$D$765,2025) -> 30 | E5: =COUNTIFS(Data!$A$2:$A$765,$A5,Data!$D$2:$D$765,2026) -> 0 | F5: =SUM(B5:E5) -> 124 | G5: =F5/$F$16 -> 0.16230366 | H5: =SUMIF(Data!$A$2:$A$765,$A5,Data!$F$2:$F$765) -> 6256803.7 | I5: =H5/$H$16 -> 0.29690532
A6: HYVA | B6: =COUNTIFS(Data!$A$2:$A$765,$A6,Data!$D$2:$D$765,2023) -> 68 | C6: =COUNTIFS(Data!$A$2:$A$765,$A6,Data!$D$2:$D$765,2024) -> 5 | D6: =COUNTIFS(Data!$A$2:$A$765,$A6,Data!$D$2:$D$765,2025) -> 26 | E6: =COUNTIFS(Data!$A$2:$A$765,$A6,Data!$D$2:$D$765,2026) -> 3 | F6: =SUM(B6:E6) -> 102 | G6: =F6/$F$16 -> 0.13350785 | H6: =SUMIF(Data!$A$2:$A$765,$A6,Data!$F$2:$F$765) -> 2030520.4 | I6: =H6/$H$16 -> 0.096354678
A7: XCMG | B7: =COUNTIFS(Data!$A$2:$A$765,$A7,Data!$D$2:$D$765,2023) -> 26 | C7: =COUNTIFS(Data!$A$2:$A$765,$A7,Data!$D$2:$D$765,2024) -> 15 | D7: =COUNTIFS(Data!$A$2:$A$765,$A7,Data!$D$2:$D$765,2025) -> 34 | E7: =COUNTIFS(Data!$A$2:$A$765,$A7,Data!$D$2:$D$765,2026) -> 13 | F7: =SUM(B7:E7) -> 88 | G7: =F7/$F$16 -> 0.11518325 | H7: =SUMIF(Data!$A$2:$A$765,$A7,Data!$F$2:$F$765) -> 2020190.6 | I7: =H7/$H$16 -> 0.095864496
A8: AMCO VEBA | B8: =COUNTIFS(Data!$A$2:$A$765,$A8,Data!$D$2:$D$765,2023) -> 29 | C8: =COUNTIFS(Data!$A$2:$A$765,$A8,Data!$D$2:$D$765,2024) -> 23 | D8: =COUNTIFS(Data!$A$2:$A$765,$A8,Data!$D$2:$D$765,2025) -> 15 | E8: =COUNTIFS(Data!$A$2:$A$765,$A8,Data!$D$2:$D$765,2026) -> 1 | F8: =SUM(B8:E8) -> 68 | G8: =F8/$F$16 -> 0.089005236 | H8: =SUMIF(Data!$A$2:$A$765,$A8,Data!$F$2:$F$765) -> 2508298.6 | I8: =H8/$H$16 -> 0.11902678
A9: HIAB | B9: =COUNTIFS(Data!$A$2:$A$765,$A9,Data!$D$2:$D$765,2023) -> 17 | C9: =COUNTIFS(Data!$A$2:$A$765,$A9,Data!$D$2:$D$765,2024) -> 15 | D9: =COUNTIFS(Data!$A$2:$A$765,$A9,Data!$D$2:$D$765,2025) -> 10 | E9: =COUNTIFS(Data!$A$2:$A$765,$A9,Data!$D$2:$D$765,2026) -> 3 | F9: =SUM(B9:E9) -> 45 | G9: =F9/$F$16 -> 0.058900524 | H9: =SUMIF(Data!$A$2:$A$765,$A9,Data!$F$2:$F$765) -> 1990548.2 | I9: =H9/$H$16 -> 0.094457872
A10: TADANO | B10: =COUNTIFS(Data!$A$2:$A$765,$A10,Data!$D$2:$D$765,2023) -> 0 | C10: =COUNTIFS(Data!$A$2:$A$765,$A10,Data!$D$2:$D$765,2024) -> 0 | D10: =COUNTIFS(Data!$A$2:$A$765,$A10,Data!$D$2:$D$765,2025) -> 13 | E10: =COUNTIFS(Data!$A$2:$A$765,$A10,Data!$D$2:$D$765,2026) -> 0 | F10: =SUM(B10:E10) -> 13 | G10: =F10/$F$16 -> 0.017015707 | H10: =SUMIF(Data!$A$2:$A$765,$A10,Data!$F$2:$F$765) -> 415385.61 | I10: =H10/$H$16 -> 0.019711374
A11: FASSI | B11: =COUNTIFS(Data!$A$2:$A$765,$A11,Data!$D$2:$D$765,2023) -> 8 | C11: =COUNTIFS(Data!$A$2:$A$765,$A11,Data!$D$2:$D$765,2024) -> 0 | D11: =COUNTIFS(Data!$A$2:$A$765,$A11,Data!$D$2:$D$765,2025) -> 3 | E11: =COUNTIFS(Data!$A$2:$A$765,$A11,Data!$D$2:$D$765,2026) -> 0 | F11: =SUM(B11:E11) -> 11 | G11: =F11/$F$16 -> 0.014397906 | H11: =SUMIF(Data!$A$2:$A$765,$A11,Data!$F$2:$F$765) -> 300109.21 | I11: =H11/$H$16 -> 0.014241141
A12: BOB-LIFT | B12: =COUNTIFS(Data!$A$2:$A$765,$A12,Data!$D$2:$D$765,2023) -> 2 | C12: =COUNTIFS(Data!$A$2:$A$765,$A12,Data!$D$2:$D$765,2024) -> 0 | D12: =COUNTIFS(Data!$A$2:$A$765,$A12,Data!$D$2:$D$765,2025) -> 3 | E12: =COUNTIFS(Data!$A$2:$A$765,$A12,Data!$D$2:$D$765,2026) -> 0 | F12: =SUM(B12:E12) -> 5 | G12: =F12/$F$16 -> 0.0065445026 | H12: =SUMIF(Data!$A$2:$A$765,$A12,Data!$F$2:$F$765) -> 45863.88 | I12: =H12/$H$16 -> 0.0021763876
A13: PM CRANES | B13: =COUNTIFS(Data!$A$2:$A$765,$A13,Data!$D$2:$D$765,2023) -> 0 | C13: =COUNTIFS(Data!$A$2:$A$765,$A13,Data!$D$2:$D$765,2024) -> 0 | D13: =COUNTIFS(Data!$A$2:$A$765,$A13,Data!$D$2:$D$765,2025) -> 0 | E13: =COUNTIFS(Data!$A$2:$A$765,$A13,Data!$D$2:$D$765,2026) -> 3 | F13: =SUM(B13:E13) -> 3 | G13: =F13/$F$16 -> 0.0039267016 | H13: =SUMIF(Data!$A$2:$A$765,$A13,Data!$F$2:$F$765) -> 56512.89 | I13: =H13/$H$16 -> 0.0026817172
A14: ZOOMLION | B14: =COUNTIFS(Data!$A$2:$A$765,$A14,Data!$D$2:$D$765,2023) -> 0 | C14: =COUNTIFS(Data!$A$2:$A$765,$A14,Data!$D$2:$D$765,2024) -> 0 | D14: =COUNTIFS(Data!$A$2:$A$765,$A14,Data!$D$2:$D$765,2025) -> 1 | E14: =COUNTIFS(Data!$A$2:$A$765,$A14,Data!$D$2:$D$765,2026) -> 1 | F14: =SUM(B14:E14) -> 2 | G14: =F14/$F$16 -> 0.002617801 | H14: =SUMIF(Data!$A$2:$A$765,$A14,Data!$F$2:$F$765) -> 93321.58 | I14: =H14/$H$16 -> 0.0044284071
A15: FERRARI | B15: =COUNTIFS(Data!$A$2:$A$765,$A15,Data!$D$2:$D$765,2023) -> 1 | C15: =COUNTIFS(Data!$A$2:$A$765,$A15,Data!$D$2:$D$765,2024) -> 0 | D15: =COUNTIFS(Data!$A$2:$A$765,$A15,Data!$D$2:$D$765,2025) -> 0 | E15: =COUNTIFS(Data!$A$2:$A$765,$A15,Data!$D$2:$D$765,2026) -> 0 | F15: =SUM(B15:E15) -> 1 | G15: =F15/$F$16 -> 0.0013089005 | H15: =SUMIF(Data!$A$2:$A$765,$A15,Data!$F$2:$F$765) -> 14247.7 | I15: =H15/$H$16 -> 0.00067609888
A16: TOTAL | F16: =SUM(F4:F15) -> 764 | H16: =SUM(H4:H15) -> 21073397
A18: Baris disorot = brand TSP & sister-brand (Hyva, Amco Veba, Ferrari).

Sheet 3. Kategori MLM per Tahun
A1: KATEGORI MAX LIFTING MOMENT — PER TAHUN
A3: Kategori Max Lifting Moment | B3: 2023 Txn | C3: 2024 Txn | D3: 2025 Txn | E3: 2026 Txn | F3: TOTAL Txn | G3: 2023 Value | H3: 2024 Value | I3: 2025 Value | J3: 2026 Value | K3: TOTAL Value
A4: Light | B4: =COUNTIFS(Data!$C$2:$C$765,"="&$A4,Data!$D$2:$D$765,2023) -> 109 | C4: =COUNTIFS(Data!$C$2:$C$765,"="&$A4,Data!$D$2:$D$765,2024) -> 52 | D4: =COUNTIFS(Data!$C$2:$C$765,"="&$A4,Data!$D$2:$D$765,2025) -> 53 | E4: =COUNTIFS(Data!$C$2:$C$765,"="&$A4,Data!$D$2:$D$765,2026) -> 34 | F4: =SUM(B4:E4) -> 248 | G4: =SUMIFS(Data!$F$2:$F$765,Data!$C$2:$C$765,"="&$A4,Data!$D$2:$D$765,2023) -> 1318388.9 | H4: =SUMIFS(Data!$F$2:$F$765,Data!$C$2:$C$765,"="&$A4,Data!$D$2:$D$765,2024) -> 839028.5 | I4: =SUMIFS(Data!$F$2:$F$765,Data!$C$2:$C$765,"="&$A4,Data!$D$2:$D$765,2025) -> 551005.17 | J4: =SUMIFS(Data!$F$2:$F$765,Data!$C$2:$C$765,"="&$A4,Data!$D$2:$D$765,2026) -> 310664.67 | K4: =SUM(G4:J4) -> 3019087.2
A5: Small | B5: =COUNTIFS(Data!$C$2:$C$765,"="&$A5,Data!$D$2:$D$765,2023) -> 68 | C5: =COUNTIFS(Data!$C$2:$C$765,"="&$A5,Data!$D$2:$D$765,2024) -> 52 | D5: =COUNTIFS(Data!$C$2:$C$765,"="&$A5,Data!$D$2:$D$765,2025) -> 75 | E5: =COUNTIFS(Data!$C$2:$C$765,"="&$A5,Data!$D$2:$D$765,2026) -> 28 | F5: =SUM(B5:E5) -> 223 | G5: =SUMIFS(Data!$F$2:$F$765,Data!$C$2:$C$765,"="&$A5,Data!$D$2:$D$765,2023) -> 1535331.2 | H5: =SUMIFS(Data!$F$2:$F$765,Data!$C$2:$C$765,"="&$A5,Data!$D$2:$D$765,2024) -> 1127848.2 | I5: =SUMIFS(Data!$F$2:$F$765,Data!$C$2:$C$765,"="&$A5,Data!$D$2:$D$765,2025) -> 1777124 | J5: =SUMIFS(Data!$F$2:$F$765,Data!$C$2:$C$765,"="&$A5,Data!$D$2:$D$765,2026) -> 596993.67 | K5: =SUM(G5:J5) -> 5037297
A6: Medium | B6: =COUNTIFS(Data!$C$2:$C$765,"="&$A6,Data!$D$2:$D$765,2023) -> 74 | C6: =COUNTIFS(Data!$C$2:$C$765,"="&$A6,Data!$D$2:$D$765,2024) -> 70 | D6: =COUNTIFS(Data!$C$2:$C$765,"="&$A6,Data!$D$2:$D$765,2025) -> 60 | E6: =COUNTIFS(Data!$C$2:$C$765,"="&$A6,Data!$D$2:$D$765,2026) -> 14 | F6: =SUM(B6:E6) -> 218 | G6: =SUMIFS(Data!$F$2:$F$765,Data!$C$2:$C$765,"="&$A6,Data!$D$2:$D$765,2023) -> 2452614.3 | H6: =SUMIFS(Data!$F$2:$F$765,Data!$C$2:$C$765,"="&$A6,Data!$D$2:$D$765,2024) -> 2703601 | I6: =SUMIFS(Data!$F$2:$F$765,Data!$C$2:$C$765,"="&$A6,Data!$D$2:$D$765,2025) -> 1759386.5 | J6: =SUMIFS(Data!$F$2:$F$765,Data!$C$2:$C$765,"="&$A6,Data!$D$2:$D$765,2026) -> 388829.32 | K6: =SUM(G6:J6) -> 7304431.1
A7: Heavy | B7: =COUNTIFS(Data!$C$2:$C$765,"="&$A7,Data!$D$2:$D$765,2023) -> 16 | C7: =COUNTIFS(Data!$C$2:$C$765,"="&$A7,Data!$D$2:$D$765,2024) -> 17 | D7: =COUNTIFS(Data!$C$2:$C$765,"="&$A7,Data!$D$2:$D$765,2025) -> 39 | E7: =COUNTIFS(Data!$C$2:$C$765,"="&$A7,Data!$D$2:$D$765,2026) -> 3 | F7: =SUM(B7:E7) -> 75 | G7: =SUMIFS(Data!$F$2:$F$765,Data!$C$2:$C$765,"="&$A7,Data!$D$2:$D$765,2023) -> 1095383 | H7: =SUMIFS(Data!$F$2:$F$765,Data!$C$2:$C$765,"="&$A7,Data!$D$2:$D$765,2024) -> 1437894.1 | I7: =SUMIFS(Data!$F$2:$F$765,Data!$C$2:$C$765,"="&$A7,Data!$D$2:$D$765,2025) -> 2951741.7 | J7: =SUMIFS(Data!$F$2:$F$765,Data!$C$2:$C$765,"="&$A7,Data!$D$2:$D$765,2026) -> 227562.74 | K7: =SUM(G7:J7) -> 5712581.6
A8: TOTAL | B8: =SUM(B4:B7) -> 267 | C8: =SUM(C4:C7) -> 191 | D8: =SUM(D4:D7) -> 227 | E8: =SUM(E4:E7) -> 79 | F8: =SUM(F4:F7) -> 764 | G8: =SUM(G4:G7) -> 6401717.4 | H8: =SUM(H4:H7) -> 6108371.8 | I8: =SUM(I4:I7) -> 7039257.3 | ... K8: =SUM(K4:K7) -> 21073397
A11: DETAIL: BRAND × TAHUN PER KATEGORI MAX LIFTING MOMENT
A13: Light | B13: 2023 | C13: 2024 | D13: 2025 | E13: 2026 | F13: Total
A14: SANY PALFINGER | B14: =COUNTIFS(Data!$A$2:$A$765,$A14,Data!$C$2:$C$765,"=Light",Data!$D$2:$D$765,2023) -> 30 | C14: =COUNTIFS(Data!$A$2:$A$765,$A14,Data!$C$2:$C$765,"=Light",Data!$D$2:$D$765,2024) -> 19 | D14: =COUNTIFS(Data!$A$2:$A$765,$A14,Data!$C$2:$C$765,"=Light",Data!$D$2:$D$765,2025) -> 30 | E14: =COUNTIFS(Data!$A$2:$A$765,$A14,Data!$C$2:$C$765,"=Light",Data!$D$2:$D$765,2026) -> 31 | F14: =SUM(B14:E14) -> 110
A15: PALFINGER | B15: =COUNTIFS(Data!$A$2:$A$765,$A15,Data!$C$2:$C$765,"=Light",Data!$D$2:$D$765,2023) -> 14 | C15: =COUNTIFS(Data!$A$2:$A$765,$A15,Data!$C$2:$C$765,"=Light",Data!$D$2:$D$765,2024) -> 24 | D15: =COUNTIFS(Data!$A$2:$A$765,$A15,Data!$C$2:$C$765,"=Light",Data!$D$2:$D$765,2025) -> 0 | E15: =COUNTIFS(Data!$A$2:$A$765,$A15,Data!$C$2:$C$765,"=Light",Data!$D$2:$D$765,2026) -> 0 | F15: =SUM(B15:E15) -> 38
A16: HYVA | B16: =COUNTIFS(Data!$A$2:$A$765,$A16,Data!$C$2:$C$765,"=Light",Data!$D$2:$D$765,2023) -> 55 | C16: =COUNTIFS(Data!$A$2:$A$765,$A16,Data!$C$2:$C$765,"=Light",Data!$D$2:$D$765,2024) -> 3 | D16: =COUNTIFS(Data!$A$2:$A$765,$A16,Data!$C$2:$C$765,"=Light",Data!$D$2:$D$765,2025) -> 13 | E16: =COUNTIFS(Data!$A$2:$A$765,$A16,Data!$C$2:$C$765,"=Light",Data!$D$2:$D$765,2026) -> 0 | F16: =SUM(B16:E16) -> 71
A17: XCMG | B17: =COUNTIFS(Data!$A$2:$A$765,$A17,Data!$C$2:$C$765,"=Light",Data!$D$2:$D$765,2023) -> 2 | C17: =COUNTIFS(Data!$A$2:$A$765,$A17,Data!$C$2:$C$765,"=Light",Data!$D$2:$D$765,2024) -> 1 | D17: =COUNTIFS(Data!$A$2:$A$765,$A17,Data!$C$2:$C$765,"=Light",Data!$D$2:$D$765,2025) -> 5 | E17: =COUNTIFS(Data!$A$2:$A$765,$A17,Data!$C$2:$C$765,"=Light",Data!$D$2:$D$765,2026) -> 3 | F17: =SUM(B17:E17) -> 11
A18: AMCO VEBA | B18: =COUNTIFS(Data!$A$2:$A$765,$A18,Data!$C$2:$C$765,"=Light",Data!$D$2:$D$765,2023) -> 4 | C18: =COUNTIFS(Data!$A$2:$A$765,$A18,Data!$C$2:$C$765,"=Light",Data!$D$2:$D$765,2024) -> 5 | D18: =COUNTIFS(Data!$A$2:$A$765,$A18,Data!$C$2:$C$765,"=Light",Data!$D$2:$D$765,2025) -> 0 | E18: =COUNTIFS(Data!$A$2:$A$765,$A18,Data!$C$2:$C$765,"=Light",Data!$D$2:$D$765,2026) -> 0 | F18: =SUM(B18:E18) -> 9
A19: HIAB | B19: =COUNTIFS(Data!$A$2:$A$765,$A19,Data!$C$2:$C$765,"=Light",Data!$D$2:$D$765,2023) -> 0 | C19: =COUNTIFS(Data!$A$2:$A$765,$A19,Data!$C$2:$C$765,"=Light",Data!$D$2:$D$765,2024) -> 0 | D19: =COUNTIFS(Data!$A$2:$A$765,$A19,Data!$C$2:$C$765,"=Light",Data!$D$2:$D$765,2025) -> 1 | E19: =COUNTIFS(Data!$A$2:$A$765,$A19,Data!$C$2:$C$765,"=Light",Data!$D$2:$D$765,2026) -> 0 | F19: =SUM(B19:E19) -> 1
A20: TADANO | B20: =COUNTIFS(Data!$A$2:$A$765,$A20,Data!$C$2:$C$765,"=Light",Data!$D$2:$D$765,2023) -> 0 | C20: =COUNTIFS(Data!$A$2:$A$765,$A20,Data!$C$2:$C$765,"=Light",Data!$D$2:$D$765,2024) -> 0 | D20: =COUNTIFS(Data!$A$2:$A$765,$A20,Data!$C$2:$C$765,"=Light",Data!$D$2:$D$765,2025) -> 2 | E20: =COUNTIFS(Data!$A$2:$A$765,$A20,Data!$C$2:$C$765,"=Light",Data!$D$2:$D$765,2026) -> 0 | F20: =SUM(B20:E20) -> 2
A21: FASSI | B21: =COUNTIFS(Data!$A$2:$A$765,$A21,Data!$C$2:$C$765,"=Light",Data!$D$2:$D$765,2023) -> 3 | C21: =COUNTIFS(Data!$A$2:$A$765,$A21,Data!$C$2:$C$765,"=Light",Data!$D$2:$D$765,2024) -> 0 | D21: =COUNTIFS(Data!$A$2:$A$765,$A21,Data!$C$2:$C$765,"=Light",Data!$D$2:$D$765,2025) -> 0 | E21: =COUNTIFS(Data!$A$2:$A$765,$A21,Data!$C$2:$C$765,"=Light",Data!$D$2:$D$765,2026) -> 0 | F21: =SUM(B21:E21) -> 3
A22: BOB-LIFT | B22: =COUNTIFS(Data!$A$2:$A$765,$A22,Data!$C$2:$C$765,"=Light",Data!$D$2:$D$765,2023) -> 0 | C22: =COUNTIFS(Data!$A$2:$A$765,$A22,Data!$C$2:$C$765,"=Light",Data!$D$2:$D$765,2024) -> 0 | D22: =COUNTIFS(Data!$A$2:$A$765,$A22,Data!$C$2:$C$765,"=Light",Data!$D$2:$D$765,2025) -> 2 | E22: =COUNTIFS(Data!$A$2:$A$765,$A22,Data!$C$2:$C$765,"=Light",Data!$D$2:$D$765,2026) -> 0 | F22: =SUM(B22:E22) -> 2
A23: PM CRANES | B23: =COUNTIFS(Data!$A$2:$A$765,$A23,Data!$C$2:$C$765,"=Light",Data!$D$2:$D$765,2023) -> 0 | C23: =COUNTIFS(Data!$A$2:$A$765,$A23,Data!$C$2:$C$765,"=Light",Data!$D$2:$D$765,2024) -> 0 | D23: =COUNTIFS(Data!$A$2:$A$765,$A23,Data!$C$2:$C$765,"=Light",Data!$D$2:$D$765,2025) -> 0 | E23: =COUNTIFS(Data!$A$2:$A$765,$A23,Data!$C$2:$C$765,"=Light",Data!$D$2:$D$765,2026) -> 0 | F23: =SUM(B23:E23) -> 0
A24: ZOOMLION | B24: =COUNTIFS(Data!$A$2:$A$765,$A24,Data!$C$2:$C$765,"=Light",Data!$D$2:$D$765,2023) -> 0 | C24: =COUNTIFS(Data!$A$2:$A$765,$A24,Data!$C$2:$C$765,"=Light",Data!$D$2:$D$765,2024) -> 0 | D24: =COUNTIFS(Data!$A$2:$A$765,$A24,Data!$C$2:$C$765,"=Light",Data!$D$2:$D$765,2025) -> 0 | E24: =COUNTIFS(Data!$A$2:$A$765,$A24,Data!$C$2:$C$765,"=Light",Data!$D$2:$D$765,2026) -> 0 | F24: =SUM(B24:E24) -> 0
A25: FERRARI | B25: =COUNTIFS(Data!$A$2:$A$765,$A25,Data!$C$2:$C$765,"=Light",Data!$D$2:$D$765,2023) -> 1 | C25: =COUNTIFS(Data!$A$2:$A$765,$A25,Data!$C$2:$C$765,"=Light",Data!$D$2:$D$765,2024) -> 0 | D25: =COUNTIFS(Data!$A$2:$A$765,$A25,Data!$C$2:$C$765,"=Light",Data!$D$2:$D$765,2025) -> 0 | E25: =COUNTIFS(Data!$A$2:$A$765,$A25,Data!$C$2:$C$765,"=Light",Data!$D$2:$D$765,2026) -> 0 | F25: =SUM(B25:E25) -> 1
A26: TOTAL | B26: =SUM(B14:B25) -> 109 | C26: =SUM(C14:C25) -> 52 | D26: =SUM(D14:D25) -> 53 | E26: =SUM(E14:E25) -> 34 | F26: =SUM(F14:F25) -> 248
A28: Small | B28: 2023 | C28: 2024 | D28: 2025 | E28: 2026 | F28: Total
A29: SANY PALFINGER | B29: =COUNTIFS(Data!$A$2:$A$765,$A29,Data!$C$2:$C$765,"=Small",Data!$D$2:$D$765,2023) -> 25 | C29: =COUNTIFS(Data!$A$2:$A$765,$A29,Data!$C$2:$C$765,"=Small",Data!$D$2:$D$765,2024) -> 32 | D29: =COUNTIFS(Data!$A$2:$A$765,$A29,Data!$C$2:$C$765,"=Small",Data!$D$2:$D$765,2025) -> 31 | E29: =COUNTIFS(Data!$A$2:$A$765,$A29,Data!$C$2:$C$765,"=Small",Data!$D$2:$D$765,2026) -> 15 | F29: =SUM(B29:E29) -> 103
A30: PALFINGER | B30: =COUNTIFS(Data!$A$2:$A$765,$A30,Data!$C$2:$C$765,"=Small",Data!$D$2:$D$765,2023) -> 5 | C30: =COUNTIFS(Data!$A$2:$A$765,$A30,Data!$C$2:$C$765,"=Small",Data!$D$2:$D$765,2024) -> 4 | D30: =COUNTIFS(Data!$A$2:$A$765,$A30,Data!$C$2:$C$765,"=Small",Data!$D$2:$D$765,2025) -> 3 | E30: =COUNTIFS(Data!$A$2:$A$765,$A30,Data!$C$2:$C$765,"=Small",Data!$D$2:$D$765,2026) -> 0 | F30: =SUM(B30:E30) -> 12
A31: HYVA | B31: =COUNTIFS(Data!$A$2:$A$765,$A31,Data!$C$2:$C$765,"=Small",Data!$D$2:$D$765,2023) -> 9 | C31: =COUNTIFS(Data!$A$2:$A$765,$A31,Data!$C$2:$C$765,"=Small",Data!$D$2:$D$765,2024) -> 1 | D31: =COUNTIFS(Data!$A$2:$A$765,$A31,Data!$C$2:$C$765,"=Small",Data!$D$2:$D$765,2025) -> 9 | E31: =COUNTIFS(Data!$A$2:$A$765,$A31,Data!$C$2:$C$765,"=Small",Data!$D$2:$D$765,2026) -> 1 | F31: =SUM(B31:E31) -> 20
A32: XCMG | B32: =COUNTIFS(Data!$A$2:$A$765,$A32,Data!$C$2:$C$765,"=Small",Data!$D$2:$D$765,2023) -> 11 | C32: =COUNTIFS(Data!$A$2:$A$765,$A32,Data!$C$2:$C$765,"=Small",Data!$D$2:$D$765,2024) -> 8 | D32: =COUNTIFS(Data!$A$2:$A$765,$A32,Data!$C$2:$C$765,"=Small",Data!$D$2:$D$765,2025) -> 11 | E32: =COUNTIFS(Data!$A$2:$A$765,$A32,Data!$C$2:$C$765,"=Small",Data!$D$2:$D$765,2026) -> 7 | F32: =SUM(B32:E32) -> 37
A33: AMCO VEBA | B33: =COUNTIFS(Data!$A$2:$A$765,$A33,Data!$C$2:$C$765,"=Small",Data!$D$2:$D$765,2023) -> 3 | C33: =COUNTIFS(Data!$A$2:$A$765,$A33,Data!$C$2:$C$765,"=Small",Data!$D$2:$D$765,2024) -> 5 | D33: =COUNTIFS(Data!$A$2:$A$765,$A33,Data!$C$2:$C$765,"=Small",Data!$D$2:$D$765,2025) -> 3 | E33: =COUNTIFS(Data!$A$2:$A$765,$A33,Data!$C$2:$C$765,"=Small",Data!$D$2:$D$765,2026) -> 0 | F33: =SUM(B33:E33) -> 11
A34: HIAB | B34: =COUNTIFS(Data!$A$2:$A$765,$A34,Data!$C$2:$C$765,"=Small",Data!$D$2:$D$765,2023) -> 8 | C34: =COUNTIFS(Data!$A$2:$A$765,$A34,Data!$C$2:$C$765,"=Small",Data!$D$2:$D$765,2024) -> 2 | D34: =COUNTIFS(Data!$A$2:$A$765,$A34,Data!$C$2:$C$765,"=Small",Data!$D$2:$D$765,2025) -> 4 | E34: =COUNTIFS(Data!$A$2:$A$765,$A34,Data!$C$2:$C$765,"=Small",Data!$D$2:$D$765,2026) -> 2 | F34: =SUM(B34:E34) -> 16
A35: TADANO | B35: =COUNTIFS(Data!$A$2:$A$765,$A35,Data!$C$2:$C$765,"=Small",Data!$D$2:$D$765,2023) -> 0 | C35: =COUNTIFS(Data!$A$2:$A$765,$A35,Data!$C$2:$C$765,"=Small",Data!$D$2:$D$765,2024) -> 0 | D35: =COUNTIFS(Data!$A$2:$A$765,$A35,Data!$C$2:$C$765,"=Small",Data!$D$2:$D$765,2025) -> 11 | E35: =COUNTIFS(Data!$A$2:$A$765,$A35,Data!$C$2:$C$765,"=Small",Data!$D$2:$D$765,2026) -> 0 | F35: =SUM(B35:E35) -> 11
A36: FASSI | B36: =COUNTIFS(Data!$A$2:$A$765,$A36,Data!$C$2:$C$765,"=Small",Data!$D$2:$D$765,2023) -> 5 | C36: =COUNTIFS(Data!$A$2:$A$765,$A36,Data!$C$2:$C$765,"=Small",Data!$D$2:$D$765,2024) -> 0 | D36: =COUNTIFS(Data!$A$2:$A$765,$A36,Data!$C$2:$C$765,"=Small",Data!$D$2:$D$765,2025) -> 2 | E36: =COUNTIFS(Data!$A$2:$A$765,$A36,Data!$C$2:$C$765,"=Small",Data!$D$2:$D$765,2026) -> 0 | F36: =SUM(B36:E36) -> 7
A37: BOB-LIFT | B37: =COUNTIFS(Data!$A$2:$A$765,$A37,Data!$C$2:$C$765,"=Small",Data!$D$2:$D$765,2023) -> 2 | C37: =COUNTIFS(Data!$A$2:$A$765,$A37,Data!$C$2:$C$765,"=Small",Data!$D$2:$D$765,2024) -> 0 | D37: =COUNTIFS(Data!$A$2:$A$765,$A37,Data!$C$2:$C$765,"=Small",Data!$D$2:$D$765,2025) -> 1 | E37: =COUNTIFS(Data!$A$2:$A$765,$A37,Data!$C$2:$C$765,"=Small",Data!$D$2:$D$765,2026) -> 0 | F37: =SUM(B37:E37) -> 3
A38: PM CRANES | B38: =COUNTIFS(Data!$A$2:$A$765,$A38,Data!$C$2:$C$765,"=Small",Data!$D$2:$D$765,2023) -> 0 | C38: =COUNTIFS(Data!$A$2:$A$765,$A38,Data!$C$2:$C$765,"=Small",Data!$D$2:$D$765,2024) -> 0 | D38: =COUNTIFS(Data!$A$2:$A$765,$A38,Data!$C$2:$C$765,"=Small",Data!$D$2:$D$765,2025) -> 0 | E38: =COUNTIFS(Data!$A$2:$A$765,$A38,Data!$C$2:$C$765,"=Small",Data!$D$2:$D$765,2026) -> 3 | F38: =SUM(B38:E38) -> 3
A39: ZOOMLION | B39: =COUNTIFS(Data!$A$2:$A$765,$A39,Data!$C$2:$C$765,"=Small",Data!$D$2:$D$765,2023) -> 0 | C39: =COUNTIFS(Data!$A$2:$A$765,$A39,Data!$C$2:$C$765,"=Small",Data!$D$2:$D$765,2024) -> 0 | D39: =COUNTIFS(Data!$A$2:$A$765,$A39,Data!$C$2:$C$765,"=Small",Data!$D$2:$D$765,2025) -> 0 | E39: =COUNTIFS(Data!$A$2:$A$765,$A39,Data!$C$2:$C$765,"=Small",Data!$D$2:$D$765,2026) -> 0 | F39: =SUM(B39:E39) -> 0
A40: FERRARI | B40: =COUNTIFS(Data!$A$2:$A$765,$A40,Data!$C$2:$C$765,"=Small",Data!$D$2:$D$765,2023) -> 0 | C40: =COUNTIFS(Data!$A$2:$A$765,$A40,Data!$C$2:$C$765,"=Small",Data!$D$2:$D$765,2024) -> 0 | D40: =COUNTIFS(Data!$A$2:$A$765,$A40,Data!$C$2:$C$765,"=Small",Data!$D$2:$D$765,2025) -> 0 | E40: =COUNTIFS(Data!$A$2:$A$765,$A40,Data!$C$2:$C$765,"=Small",Data!$D$2:$D$765,2026) -> 0 | F40: =SUM(B40:E40) -> 0
A41: TOTAL | B41: =SUM(B29:B40) -> 68 | C41: =SUM(C29:C40) -> 52 | D41: =SUM(D29:D40) -> 75 | E41: =SUM(E29:E40) -> 28 | F41: =SUM(F29:F40) -> 223
A43: Medium | B43: 2023 | C43: 2024 | D43: 2025 | E43: 2026 | F43: Total
A44: SANY PALFINGER | B44: =COUNTIFS(Data!$A$2:$A$765,$A44,Data!$C$2:$C$765,"=Medium",Data!$D$2:$D$765,2023) -> 26 | C44: =COUNTIFS(Data!$A$2:$A$765,$A44,Data!$C$2:$C$765,"=Medium",Data!$D$2:$D$765,2024) -> 23 | D44: =COUNTIFS(Data!$A$2:$A$765,$A44,Data!$C$2:$C$765,"=Medium",Data!$D$2:$D$765,2025) -> 30 | E44: =COUNTIFS(Data!$A$2:$A$765,$A44,Data!$C$2:$C$765,"=Medium",Data!$D$2:$D$765,2026) -> 9 | F44: =SUM(B44:E44) -> 88
A45: PALFINGER | B45: =COUNTIFS(Data!$A$2:$A$765,$A45,Data!$C$2:$C$765,"=Medium",Data!$D$2:$D$765,2023) -> 9 | C45: =COUNTIFS(Data!$A$2:$A$765,$A45,Data!$C$2:$C$765,"=Medium",Data!$D$2:$D$765,2024) -> 17 | D45: =COUNTIFS(Data!$A$2:$A$765,$A45,Data!$C$2:$C$765,"=Medium",Data!$D$2:$D$765,2025) -> 5 | E45: =COUNTIFS(Data!$A$2:$A$765,$A45,Data!$C$2:$C$765,"=Medium",Data!$D$2:$D$765,2026) -> 0 | F45: =SUM(B45:E45) -> 31
A46: HYVA | B46: =COUNTIFS(Data!$A$2:$A$765,$A46,Data!$C$2:$C$765,"=Medium",Data!$D$2:$D$765,2023) -> 1 | C46: =COUNTIFS(Data!$A$2:$A$765,$A46,Data!$C$2:$C$765,"=Medium",Data!$D$2:$D$765,2024) -> 1 | D46: =COUNTIFS(Data!$A$2:$A$765,$A46,Data!$C$2:$C$765,"=Medium",Data!$D$2:$D$765,2025) -> 1 | E46: =COUNTIFS(Data!$A$2:$A$765,$A46,Data!$C$2:$C$765,"=Medium",Data!$D$2:$D$765,2026) -> 1 | F46: =SUM(B46:E46) -> 4
...

Sheet 4. Trend Momentum
A1: TREND MOMENTUM — VOLUME, VALUE & MODEL TERPOPULER
A3: Year | B3: Txn | C3: Value (USD) | D3: Avg Price (USD) | E3: YoY Txn | F3: YoY Value
A4: 2023 | B4: =COUNTIF(Data!$D$2:$D$765,2023) -> 267 | C4: =SUMIF(Data!$D$2:$D$765,2023,Data!$F$2:$F$765) -> 6401717.4 | D4: =IFERROR(C4/B4,0) -> 23976.47
A5: 2024 | B5: =COUNTIF(Data!$D$2:$D$765,2024) -> 191 | C5: =SUMIF(Data!$D$2:$D$765,2024,Data!$F$2:$F$765) -> 6108371.8 | D5: =IFERROR(C5/B5,0) -> 31981.004 | E5: =IFERROR(B5/B4-1,0) -> -0.28464419 | F5: =IFERROR(C5/C4-1,0) -> -0.04582296
A6: 2025 | B6: =COUNTIF(Data!$D$2:$D$765,2025) -> 227 | C6: =SUMIF(Data!$D$2:$D$765,2025,Data!$F$2:$F$765) -> 7039257.3 | D6: =IFERROR(C6/B6,0) -> 31009.944 | E6: =IFERROR(B6/B5-1,0) -> 0.18848168 | F6: =IFERROR(C6/C5-1,0) -> 0.15239504
A7: 2026 YTD (s/d Aug) | B7: =COUNTIF(Data!$D$2:$D$765,2026) -> 79 | C7: =SUMIF(Data!$D$2:$D$765,2026,Data!$F$2:$F$765) -> 1524050.4 | D7: =IFERROR(C7/B7,0) -> 19291.777 | E7: =IFERROR(B7/B6-1,0) -> -0.65198238 | F7: =IFERROR(C7/C6-1,0) -> -0.78349273
A8: TOTAL 4 TAHUN | B8: =SUM(B4:B7) -> 764 | C8: =SUM(C4:C7) -> 21073397 | D8: =IFERROR(C8/B8,0) -> 27582.98
A11: TOP 10 MODEL TERPOPULER
A12: Model | B12: Brand | C12: Kategori Max Lifting Moment | D12: Txn | E12: Total Value (USD) | F12: Avg Price (USD) | G12: GVW Rekomendasi (ton)
A13: SANY PALFINGER SPK8500 | B13: SANY PALFINGER | C13: Light | D13: =COUNTIF(Data!$B$2:$B$765,$A13) -> 48 | E13: =SUMIF(Data!$B$2:$B$765,$A13,Data!$F$2:$F$765) -> 496852.07 | F13: =IFERROR(E13/D13,0) -> 10351.085 | G13: =INDEX(Data!$N$2:$N$765,MATCH($A13,Data!$B$2:$B$765,0)) -> 10
A14: HYVA HB60 | B14: HYVA | C14: Light | D14: =COUNTIF(Data!$B$2:$B$765,$A14) -> 44 | E14: =SUMIF(Data!$B$2:$B$765,$A14,Data!$F$2:$F$765) -> 440848.34 | F14: =IFERROR(E14/D14,0) -> 10019.28 | G14: =INDEX(Data!$N$2:$N$765,MATCH($A14,Data!$B$2:$B$765,0)) -> 10
A15: SANY PALFINGER SPK23500 | B15: SANY PALFINGER | C15: Small | D15: =COUNTIF(Data!$B$2:$B$765,$A15) -> 42 | E15: =SUMIF(Data!$B$2:$B$765,$A15,Data!$F$2:$F$765) -> 759487.38 | F15: =IFERROR(E15/D15,0) -> 18083.033 | G15: =INDEX(Data!$N$2:$N$765,MATCH($A15,Data!$B$2:$B$765,0)) -> 19
A16: SANY PALFINGER SPK8500A | B16: SANY PALFINGER | C16: Light | D16: =COUNTIF(Data!$B$2:$B$765,$A16) -> 42 | E16: =SUMIF(Data!$B$2:$B$765,$A16,Data!$F$2:$F$765) -> 434294.35 | F16: =IFERROR(E16/D16,0) -> 10340.342 | G16: =INDEX(Data!$N$2:$N$765,MATCH($A16,Data!$B$2:$B$765,0)) -> 10
A17: PALFINGER PK 53002 SH B | B17: PALFINGER | C17: Heavy | D17: =COUNTIF(Data!$B$2:$B$765,$A17) -> 38 | E17: =SUMIF(Data!$B$2:$B$765,$A17,Data!$F$2:$F$765) -> 2898827.7 | F17: =IFERROR(E17/D17,0) -> 76284.939 | G17: =INDEX(Data!$N$2:$N$765,MATCH($A17,Data!$B$2:$B$765,0)) -> 42
A18: PALFINGER PK 8501 SLD 3 A | B18: PALFINGER | C18: Light | D18: =COUNTIF(Data!$B$2:$B$765,$A18) -> 34 | E18: =SUMIF(Data!$B$2:$B$765,$A18,Data!$F$2:$F$765) -> 772478.79 | F18: =IFERROR(E18/D18,0) -> 22719.964 | G18: =INDEX(Data!$N$2:$N$765,MATCH($A18,Data!$B$2:$B$765,0)) -> 10
A19: AMCO VEBA V825 | B19: AMCO VEBA | C19: Medium | D19: =COUNTIF(Data!$B$2:$B$765,$A19) -> 31 | E19: =SUMIF(Data!$B$2:$B$765,$A19,Data!$F$2:$F$765) -> 900512.94 | F19: =IFERROR(E19/D19,0) -> 29048.805 | G19: =INDEX(Data!$N$2:$N$765,MATCH($A19,Data!$B$2:$B$765,0)) -> 19
A20: SANY PALFINGER SPK23500B | B20: SANY PALFINGER | C20: Small | D20: =COUNTIF(Data!$B$2:$B$765,$A20) -> 28 | E20: =SUMIF(Data!$B$2:$B$765,$A20,Data!$F$2:$F$765) -> 555241 | F20: =IFERROR(E20/D20,0) -> 19830.036 | G20: =INDEX(Data!$N$2:$N$765,MATCH($A20,Data!$B$2:$B$765,0)) -> 19
A21: SANY PALFINGER SPK36080 | B21: SANY PALFINGER | C21: Medium | D21: =COUNTIF(Data!$B$2:$B$765,$A21) -> 23 | E21: =SUMIF(Data!$B$2:$B$765,$A21,Data!$F$2:$F$765) -> 537915.36 | F21: =IFERROR(E21/D21,0) -> 23387.624 | G21: =INDEX(Data!$N$2:$N$765,MATCH($A21,Data!$B$2:$B$765,0)) -> 26
A22: HIAB X-CLX 388 | B22: HIAB | C22: Medium | D22: =COUNTIF(Data!$B$2:$B$765,$A22) -> 21 | E22: =SUMIF(Data!$B$2:$B$765,$A22,Data!$F$2:$F$765) -> 898988.75 | F22: =IFERROR(E22/D22,0) -> 42808.988 | G22: =INDEX(Data!$N$2:$N$765,MATCH($A22,Data!$B$2:$B$765,0)) -> 26
A25: VOLUME PER KATEGORI MAX LIFTING MOMENT (TOTAL)
A26: Kategori Max Lifting Moment | B26: Txn | C26: Share | D26: Value (USD)
A27: Light | B27: ='3. Kategori MLM per Tahun'!$F$4 -> 248 | C27: =IFERROR(B27/764,0) -> 0.32460733 | D27: ='3. Kategori MLM per Tahun'!$K$4 -> 3019087.2
A28: Small | B28: ='3. Kategori MLM per Tahun'!$F$5 -> 223 | C28: =IFERROR(B28/764,0) -> 0.29188482 | D28: ='3. Kategori MLM per Tahun'!$K$5 -> 5037297
A29: Medium | B29: ='3. Kategori MLM per Tahun'!$F$6 -> 218 | C29: =IFERROR(B29/764,0) -> 0.28534031 | D29: ='3. Kategori MLM per Tahun'!$K$6 -> 7304431.1
A30: Heavy | B30: ='3. Kategori MLM per Tahun'!$F$7 -> 75 | C30: =IFERROR(B30/764,0) -> 0.098167539 | D30: ='3. Kategori MLM per Tahun'!$K$7 -> 5712581.6

Sheet 5. Value Pool
A1: VALUE POOL — USD & QTY × KATEGORI MAX LIFTING MOMENT
A3: Brand | B3: Light | C3: Small | D3: Medium | E3: Heavy | F3: TOTAL (USD) | G3: Share
A4: SANY PALFINGER | B4: =SUMIFS(Data!$F$2:$F$765,Data!$A$2:$A$765,$A4,Data!$C$2:$C$765,"="&B$3) -> 1100916.7 | C4: =SUMIFS(Data!$F$2:$F$765,Data!$A$2:$A$765,$A4,Data!$C$2:$C$765,"="&C$3) -> 1853336.9 | D4: =SUMIFS(Data!$F$2:$F$765,Data!$A$2:$A$765,$A4,Data!$C$2:$C$765,"="&D$3) -> 2317944.5 | E4: =SUMIFS(Data!$F$2:$F$765,Data!$A$2:$A$765,$A4,Data!$C$2:$C$765,"="&E$3) -> 69396.46 | F4: =SUM(B4:E4) -> 5341594.6 | G4: =F4/$F$16 -> 0.25347573
A5: PALFINGER | B5: =SUMIFS(Data!$F$2:$F$765,Data!$A$2:$A$765,$A5,Data!$C$2:$C$765,"="&B$3) -> 836947.19 | C5: =SUMIFS(Data!$F$2:$F$765,Data!$A$2:$A$765,$A5,Data!$C$2:$C$765,"="&C$3) -> 414041.25 | D5: =SUMIFS(Data!$F$2:$F$765,Data!$A$2:$A$765,$A5,Data!$C$2:$C$765,"="&D$3) -> 1701283.7 | E5: =SUMIFS(Data!$F$2:$F$765,Data!$A$2:$A$765,$A5,Data!$C$2:$C$765,"="&E$3) -> 3304531.6 | F5: =SUM(B5:E5) -> 6256803.7 | G5: =F5/$F$16 -> 0.29690532
A6: HYVA | B6: =SUMIFS(Data!$F$2:$F$765,Data!$A$2:$A$765,$A6,Data!$C$2:$C$765,"="&B$3) -> 765621.56 | C6: =SUMIFS(Data!$F$2:$F$765,Data!$A$2:$A$765,$A6,Data!$C$2:$C$765,"="&C$3) -> 570766.51 | D6: =SUMIFS(Data!$F$2:$F$765,Data!$A$2:$A$765,$A6,Data!$C$2:$C$765,"="&D$3) -> 197711.24 | E6: =SUMIFS(Data!$F$2:$F$765,Data!$A$2:$A$765,$A6,Data!$C$2:$C$765,"="&E$3) -> 496421.06 | F6: =SUM(B6:E6) -> 2030520.4 | G6: =F6/$F$16 -> 0.096354678
A7: XCMG | B7: =SUMIFS(Data!$F$2:$F$765,Data!$A$2:$A$765,$A7,Data!$C$2:$C$765,"="&B$3) -> 91096.69 | C7: =SUMIFS(Data!$F$2:$F$765,Data!$A$2:$A$765,$A7,Data!$C$2:$C$765,"="&C$3) -> 635195.91 | D7: =SUMIFS(Data!$F$2:$F$765,Data!$A$2:$A$765,$A7,Data!$C$2:$C$765,"="&D$3) -> 912318.61 | E7: =SUMIFS(Data!$F$2:$F$765,Data!$A$2:$A$765,$A7,Data!$C$2:$C$765,"="&E$3) -> 381579.36 | F7: =SUM(B7:E7) -> 2020190.6 | G7: =F7/$F$16 -> 0.095864496
A8: AMCO VEBA | B8: =SUMIFS(Data!$F$2:$F$765,Data!$A$2:$A$765,$A8,Data!$C$2:$C$765,"="&B$3) -> 106936.18 | C8: =SUMIFS(Data!$F$2:$F$765,Data!$A$2:$A$765,$A8,Data!$C$2:$C$765,"="&C$3) -> 222088.83 | D8: =SUMIFS(Data!$F$2:$F$765,Data!$A$2:$A$765,$A8,Data!$C$2:$C$765,"="&D$3) -> 1117505.7 | E8: =SUMIFS(Data!$F$2:$F$765,Data!$A$2:$A$765,$A8,Data!$C$2:$C$765,"="&E$3) -> 1061767.8 | F8: =SUM(B8:E8) -> 2508298.6 | G8: =F8/$F$16 -> 0.11902678
A9: HIAB | B9: =SUMIFS(Data!$F$2:$F$765,Data!$A$2:$A$765,$A9,Data!$C$2:$C$765,"="&B$3) -> 25352.24 | C9: =SUMIFS(Data!$F$2:$F$765,Data!$A$2:$A$765,$A9,Data!$C$2:$C$765,"="&C$3) -> 677736.78 | D9: =SUMIFS(Data!$F$2:$F$765,Data!$A$2:$A$765,$A9,Data!$C$2:$C$765,"="&D$3) -> 1057667.3 | E9: =SUMIFS(Data!$F$2:$F$765,Data!$A$2:$A$765,$A9,Data!$C$2:$C$765,"="&E$3) -> 229791.9 | F9: =SUM(B9:E9) -> 1990548.2 | G9: =F9/$F$16 -> 0.094457872
A10: TADANO | B10: =SUMIFS(Data!$F$2:$F$765,Data!$A$2:$A$765,$A10,Data!$C$2:$C$765,"="&B$3) -> 33666.28 | C10: =SUMIFS(Data!$F$2:$F$765,Data!$A$2:$A$765,$A10,Data!$C$2:$C$765,"="&C$3) -> 381719.33 | D10: =SUMIFS(Data!$F$2:$F$765,Data!$A$2:$A$765,$A10,Data!$C$2:$C$765,"="&D$3) -> 0 | E10: =SUMIFS(Data!$F$2:$F$765,Data!$A$2:$A$765,$A10,Data!$C$2:$C$765,"="&E$3) -> 0 | F10: =SUM(B10:E10) -> 415385.61 | G10: =F10/$F$16 -> 0.019711374
A11: FASSI | B11: =SUMIFS(Data!$F$2:$F$765,Data!$A$2:$A$765,$A11,Data!$C$2:$C$765,"="&B$3) -> 33418.84 | C11: =SUMIFS(Data!$F$2:$F$765,Data!$A$2:$A$765,$A11,Data!$C$2:$C$765,"="&C$3) -> 190918.58 | D11: =SUMIFS(Data!$F$2:$F$765,Data!$A$2:$A$765,$A11,Data!$C$2:$C$765,"="&D$3) -> 0 | E11: =SUMIFS(Data!$F$2:$F$765,Data!$A$2:$A$765,$A11,Data!$C$2:$C$765,"="&E$3) -> 75771.79 | F11: =SUM(B11:E11) -> 300109.21 | G11: =F11/$F$16 -> 0.014241141
A12: BOB-LIFT | B12: =SUMIFS(Data!$F$2:$F$765,Data!$A$2:$A$765,$A12,Data!$C$2:$C$765,"="&B$3) -> 10883.85 | C12: =SUMIFS(Data!$F$2:$F$765,Data!$A$2:$A$765,$A12,Data!$C$2:$C$765,"="&C$3) -> 34980.03 | D12: =SUMIFS(Data!$F$2:$F$765,Data!$A$2:$A$765,$A12,Data!$C$2:$C$765,"="&D$3) -> 0 | E12: =SUMIFS(Data!$F$2:$F$765,Data!$A$2:$A$765,$A12,Data!$C$2:$C$765,"="&E$3) -> 0 | F12: =SUM(B12:E12) -> 45863.88 | G12: =F12/$F$16 -> 0.0021763876
A13: PM CRANES | B13: =SUMIFS(Data!$F$2:$F$765,Data!$A$2:$A$765,$A13,Data!$C$2:$C$765,"="&B$3) -> 0 | C13: =SUMIFS(Data!$F$2:$F$765,Data!$A$2:$A$765,$A13,Data!$C$2:$C$765,"="&C$3) -> 56512.89 | D13: =SUMIFS(Data!$F$2:$F$765,Data!$A$2:$A$765,$A13,Data!$C$2:$C$765,"="&D$3) -> 0 | E13: =SUMIFS(Data!$F$2:$F$765,Data!$A$2:$A$765,$A13,Data!$C$2:$C$765,"="&E$3) -> 0 | F13: =SUM(B13:E13) -> 56512.89 | G13: =F13/$F$16 -> 0.0026817172
A14: ZOOMLION | B14: =SUMIFS(Data!$F$2:$F$765,Data!$A$2:$A$765,$A14,Data!$C$2:$C$765,"="&B$3) -> 0 | C14: =SUMIFS(Data!$F$2:$F$765,Data!$A$2:$A$765,$A14,Data!$C$2:$C$765,"="&C$3) -> 0 | D14: =SUMIFS(Data!$F$2:$F$765,Data!$A$2:$A$765,$A14,Data!$C$2:$C$765,"="&D$3) -> 0 | E14: =SUMIFS(Data!$F$2:$F$765,Data!$A$2:$A$765,$A14,Data!$C$2:$C$765,"="&E$3) -> 93321.58 | F14: =SUM(B14:E14) -> 93321.58 | G14: =F14/$F$16 -> 0.0044284071
A15: FERRARI | B15: =SUMIFS(Data!$F$2:$F$765,Data!$A$2:$A$765,$A15,Data!$C$2:$C$765,"="&B$3) -> 14247.7 | C15: =SUMIFS(Data!$F$2:$F$765,Data!$A$2:$A$765,$A15,Data!$C$2:$C$765,"="&C$3) -> 0 | D15: =SUMIFS(Data!$F$2:$F$765,Data!$A$2:$A$765,$A15,Data!$C$2:$C$765,"="&D$3) -> 0 | E15: =SUMIFS(Data!$F$2:$F$765,Data!$A$2:$A$765,$A15,Data!$C$2:$C$765,"="&E$3) -> 0 | F15: =SUM(B15:E15) -> 14247.7 | G15: =F15/$F$16 -> 0.00067609888
A16: TOTAL | B16: =SUM(B4:B15) -> 3019087.2 | C16: =SUM(C4:C15) -> 5037297 | D16: =SUM(D4:D15) -> 7304431.1 | E16: =SUM(E4:E15) -> 5712581.6 | F16: =SUM(F4:F15) -> 21073397
A19: QTY (UNITS) × KATEGORI MAX LIFTING MOMENT
A21: Brand | B21: Light | C21: Small | D21: Medium | E21: Heavy | F21: TOTAL (Units) | G21: Share
A22: SANY PALFINGER | B22: =COUNTIFS(Data!$A$2:$A$765,$A22,Data!$C$2:$C$765,"="&B$21) -> 110 | C22: =COUNTIFS(Data!$A$2:$A$765,$A22,Data!$C$2:$C$765,"="&C$21) -> 103 | D22: =COUNTIFS(Data!$A$2:$A$765,$A22,Data!$C$2:$C$765,"="&D$21) -> 88 | E22: =COUNTIFS(Data!$A$2:$A$765,$A22,Data!$C$2:$C$765,"="&E$21) -> 1 | F22: =SUM(B22:E22) -> 302 | G22: =F22/$F$34 -> 0.39528796
A23: PALFINGER | B23: =COUNTIFS(Data!$A$2:$A$765,$A23,Data!$C$2:$C$765,"="&B$21) -> 38 | C23: =COUNTIFS(Data!$A$2:$A$765,$A23,Data!$C$2:$C$765,"="&C$21) -> 12 | D23: =COUNTIFS(Data!$A$2:$A$765,$A23,Data!$C$2:$C$765,"="&D$21) -> 31 | E23: =COUNTIFS(Data!$A$2:$A$765,$A23,Data!$C$2:$C$765,"="&E$21) -> 43 | F23: =SUM(B23:E23) -> 124 | G23: =F23/$F$34 -> 0.16230366
A24: HYVA | B24: =COUNTIFS(Data!$A$2:$A$765,$A24,Data!$C$2:$C$765,"="&B$21) -> 71 | C24: =COUNTIFS(Data!$A$2:$A$765,$A24,Data!$C$2:$C$765,"="&C$21) -> 20 | D24: =COUNTIFS(Data!$A$2:$A$765,$A24,Data!$C$2:$C$765,"="&D$21) -> 4 | E24: =COUNTIFS(Data!$A$2:$A$765,$A24,Data!$C$2:$C$765,"="&E$21) -> 7 | F24: =SUM(B24:E24) -> 102 | G24: =F24/$F$34 -> 0.13350785
A25: XCMG | B25: =COUNTIFS(Data!$A$2:$A$765,$A25,Data!$C$2:$C$765,"="&B$21) -> 11 | C25: =COUNTIFS(Data!$A$2:$A$765,$A25,Data!$C$2:$C$765,"="&C$21) -> 37 | D25: =COUNTIFS(Data!$A$2:$A$765,$A25,Data!$C$2:$C$765,"="&D$21) -> 33 | E25: =COUNTIFS(Data!$A$2:$A$765,$A25,Data!$C$2:$C$765,"="&E$21) -> 7 | F25: =SUM(B25:E25) -> 88 | G25: =F25/$F$34 -> 0.11518325
A26: AMCO VEBA | B26: =COUNTIFS(Data!$A$2:$A$765,$A26,Data!$C$2:$C$765,"="&B$21) -> 9 | C26: =COUNTIFS(Data!$A$2:$A$765,$A26,Data!$C$2:$C$765,"="&C$21) -> 11 | D26: =COUNTIFS(Data!$A$2:$A$765,$A26,Data!$C$2:$C$765,"="&D$21) -> 36 | E26: =COUNTIFS(Data!$A$2:$A$765,$A26,Data!$C$2:$C$765,"="&E$21) -> 12 | F26: =SUM(B26:E26) -> 68 | G26: =F26/$F$34 -> 0.089005236
A27: HIAB | B27: =COUNTIFS(Data!$A$2:$A$765,$A27,Data!$C$2:$C$765,"="&B$21) -> 1 | C27: =COUNTIFS(Data!$A$2:$A$765,$A27,Data!$C$2:$C$765,"="&C$21) -> 16 | D27: =COUNTIFS(Data!$A$2:$A$765,$A27,Data!$C$2:$C$765,"="&D$21) -> 26 | E27: =COUNTIFS(Data!$A$2:$A$765,$A27,Data!$C$2:$C$765,"="&E$21) -> 2 | F27: =SUM(B27:E27) -> 45 | G27: =F27/$F$34 -> 0.058900524
A28: TADANO | B28: =COUNTIFS(Data!$A$2:$A$765,$A28,Data!$C$2:$C$765,"="&B$21) -> 2 | C28: =COUNTIFS(Data!$A$2:$A$765,$A28,Data!$C$2:$C$765,"="&C$21) -> 11 | D28: =COUNTIFS(Data!$A$2:$A$765,$A28,Data!$C$2:$C$765,"="&D$21) -> 0 | E28: =COUNTIFS(Data!$A$2:$A$765,$A28,Data!$C$2:$C$765,"="&E$21) -> 0 | F28: =SUM(B28:E28) -> 13 | G28: =F28/$F$34 -> 0.017015707
A29: FASSI | B29: =COUNTIFS(Data!$A$2:$A$765,$A29,Data!$C$2:$C$765,"="&B$21) -> 3 | C29: =COUNTIFS(Data!$A$2:$A$765,$A29,Data!$C$2:$C$765,"="&C$21) -> 7 | D29: =COUNTIFS(Data!$A$2:$A$765,$A29,Data!$C$2:$C$765,"="&D$21) -> 0 | E29: =COUNTIFS(Data!$A$2:$A$765,$A29,Data!$C$2:$C$765,"="&E$21) -> 1 | F29: =SUM(B29:E29) -> 11 | G29: =F29/$F$34 -> 0.014397906
A30: BOB-LIFT | B30: =COUNTIFS(Data!$A$2:$A$765,$A30,Data!$C$2:$C$765,"="&B$21) -> 2 | C30: =COUNTIFS(Data!$A$2:$A$765,$A30,Data!$C$2:$C$765,"="&C$21) -> 3 | D30: =COUNTIFS(Data!$A$2:$A$765,$A30,Data!$C$2:$C$765,"="&D$21) -> 0 | E30: =COUNTIFS(Data!$A$2:$A$765,$A30,Data!$C$2:$C$765,"="&E$21) -> 0 | F30: =SUM(B30:E30) -> 5 | G30: =F30/$F$34 -> 0.0065445026
A31: PM CRANES | B31: =COUNTIFS(Data!$A$2:$A$765,$A31,Data!$C$2:$C$765,"="&B$21) -> 0 | C31: =COUNTIFS(Data!$A$2:$A$765,$A31,Data!$C$2:$C$765,"="&C$21) -> 3 | D31: =COUNTIFS(Data!$A$2:$A$765,$A31,Data!$C$2:$C$765,"="&D$21) -> 0 | E31: =COUNTIFS(Data!$A$2:$A$765,$A31,Data!$C$2:$C$765,"="&E$21) -> 0 | F31: =SUM(B31:E31) -> 3 | G31: =F31/$F$34 -> 0.0039267016
A32: ZOOMLION | B32: =COUNTIFS(Data!$A$2:$A$765,$A32,Data!$C$2:$C$765,"="&B$21) -> 0 | C32: =COUNTIFS(Data!$A$2:$A$765,$A32,Data!$C$2:$C$765,"="&C$21) -> 0 | D32: =COUNTIFS(Data!$A$2:$A$765,$A32,Data!$C$2:$C$765,"="&D$21) -> 0 | E32: =COUNTIFS(Data!$A$2:$A$765,$A32,Data!$C$2:$C$765,"="&E$21) -> 2 | F32: =SUM(B32:E32) -> 2 | G32: =F32/$F$34 -> 0.002617801
A33: FERRARI | B33: =COUNTIFS(Data!$A$2:$A$765,$A33,Data!$C$2:$C$765,"="&B$21) -> 1 | C33: =COUNTIFS(Data!$A$2:$A$765,$A33,Data!$C$2:$C$765,"="&C$21) -> 0 | D33: =COUNTIFS(Data!$A$2:$A$765,$A33,Data!$C$2:$C$765,"="&D$21) -> 0 | E33: =COUNTIFS(Data!$A$2:$A$765,$A33,Data!$C$2:$C$765,"="&E$21) -> 0 | F33: =SUM(B33:E33) -> 1 | G33: =F33/$F$34 -> 0.0013089005
A34: TOTAL | B34: =SUM(B22:B33) -> 248 | C34: =SUM(C22:C33) -> 223 | D34: =SUM(D22:D33) -> 218 | E34: =SUM(E22:E33) -> 75 | F34: =SUM(F22:F33) -> 764
A37: QTY × KATEGORI MAX LIFTING MOMENT × TAHUN (PER BRAND)
A39: Brand: SANY PALFINGER
A40: Kategori Max Lifting Moment | B40: 2023 | C40: 2024 | D40: 2025 | E40: 2026 | F40: Total
A41: Light | B41: =COUNTIFS(Data!$A$2:$A$765,"=SANY PALFINGER",Data!$C$2:$C$765,"="&$A41,Data!$D$2:$D$765,2023) -> 30 | C41: =COUNTIFS(Data!$A$2:$A$765,"=SANY PALFINGER",Data!$C$2:$C$765,"="&$A41,Data!$D$2:$D$765,2024) -> 19 | D41: =COUNTIFS(Data!$A$2:$A$765,"=SANY PALFINGER",Data!$C$2:$C$765,"="&$A41,Data!$D$2:$D$765,2025) -> 30 | E41: =COUNTIFS(Data!$A$2:$A$765,"=SANY PALFINGER",Data!$C$2:$C$765,"="&$A41,Data!$D$2:$D$765,2026) -> 31 | F41: =SUM(B41:E41) -> 110
A42: Small | B42: =COUNTIFS(Data!$A$2:$A$765,"=SANY PALFINGER",Data!$C$2:$C$765,"="&$A42,Data!$D$2:$D$765,2023) -> 25 | C42: =COUNTIFS(Data!$A$2:$A$765,"=SANY PALFINGER",Data!$C$2:$C$765,"="&$A42,Data!$D$2:$D$765,2024) -> 32 | D42: =COUNTIFS(Data!$A$2:$A$765,"=SANY PALFINGER",Data!$C$2:$C$765,"="&$A42,Data!$D$2:$D$765,2025) -> 31 | E42: =COUNTIFS(Data!$A$2:$A$765,"=SANY PALFINGER",Data!$C$2:$C$765,"="&$A42,Data!$D$2:$D$765,2026) -> 15 | F42: =SUM(B42:E42) -> 103
A43: Medium | B43: =COUNTIFS(Data!$A$2:$A$765,"=SANY PALFINGER",Data!$C$2:$C$765,"="&$A43,Data!$D$2:$D$765,2023) -> 26 | C43: =COUNTIFS(Data!$A$2:$A$765,"=SANY PALFINGER",Data!$C$2:$C$765,"="&$A43,Data!$D$2:$D$765,2024) -> 23 | D43: =COUNTIFS(Data!$A$2:$A$765,"=SANY PALFINGER",Data!$C$2:$C$765,"="&$A43,Data!$D$2:$D$765,2025) -> 30 | E43: =COUNTIFS(Data!$A$2:$A$765,"=SANY PALFINGER",Data!$C$2:$C$765,"="&$A43,Data!$D$2:$D$765,2026) -> 9 | F43: =SUM(B43:E43) -> 88
A44: Heavy | B44: =COUNTIFS(Data!$A$2:$A$765,"=SANY PALFINGER",Data!$C$2:$C$765,"="&$A44,Data!$D$2:$D$765,2023) -> 0 | C44: =COUNTIFS(Data!$A$2:$A$765,"=SANY PALFINGER",Data!$C$2:$C$765,"="&$A44,Data!$D$2:$D$765,2024) -> 0 | D44: =COUNTIFS(Data!$A$2:$A$765,"=SANY PALFINGER",Data!$C$2:$C$765,"="&$A44,Data!$D$2:$D$765,2025) -> 1 | E44: =COUNTIFS(Data!$A$2:$A$765,"=SANY PALFINGER",Data!$C$2:$C$765,"="&$A44,Data!$D$2:$D$765,2026) -> 0 | F44: =SUM(B44:E44) -> 1
A45: TOTAL | B45: =SUM(B41:B44) -> 81 | C45: =SUM(C41:C44) -> 74 | D45: =SUM(D41:D44) -> 92 | E45: =SUM(E41:E44) -> 55 | F45: =SUM(F41:F44) -> 302
A47: Brand: PALFINGER
A48: Kategori Max Lifting Moment | B48: 2023 | C48: 2024 | D48: 2025 | E48: 2026 | F48: Total
...

Sheet 6. GVW Pairing per Model
A1: PAIRING TRUK — GVW REKOMENDASI PER MODEL CRANE (BASIS KURVA F.LLI FERRARI)
A3: Brand | B3: Model | C3: Txn | D3: Max Lifting Moment asli (tm) | E3: Max Lifting Moment dibulatkan (tm) | F3: Kategori Max Lifting Moment | G3: GVW Rekomendasi (ton) | H3: Model Ferrari Acuan | I3: Status Verifikasi
A4: SANY PALFINGER | B4: SANY PALFINGER SPK15500 | C4: =COUNTIFS(Data!$A$2:$A$765,$A4,Data!$B$2:$B$765,$B4) -> 12 | D4: =IF(Data!K82="","",Data!K82) -> 14.6 | E4: =IF(Data!L82="","",Data!L82) -> 15 | F4: =IF(Data!C82="","",Data!C82) -> Small | G4: =IF(Data!N82="","",Data!N82) -> 19 | H4: =IF(Data!O82="","",Data!O82) -> 6238B | I4: =IF(Data!M82="","",Data!M82) -> Terverifikasi — spek resmi
A5: SANY PALFINGER | B5: SANY PALFINGER SPK15500B | C5: =COUNTIFS(Data!$A$2:$A$765,$A5,Data!$B$2:$B$765,$B5) -> 12 | D5: =IF(Data!K93="","",Data!K93) -> 14.6 | E5: =IF(Data!L93="","",Data!L93) -> 15 | F5: =IF(Data!C93="","",Data!C93) -> Small | G5: =IF(Data!N93="","",Data!N93) -> 19 | H5: =IF(Data!O93="","",Data!O93) -> 6238B | I5: =IF(Data!M93="","",Data!M93) -> Terverifikasi — spek resmi
A6: SANY PALFINGER | B6: SANY PALFINGER SPK18500 | C6: =COUNTIFS(Data!$A$2:$A$765,$A6,Data!$B$2:$B$765,$B6) -> 5 | D6: =IF(Data!K99="","",Data!K99) -> 18.5 | E6: =IF(Data!L99="","",Data!L99) -> 19 | F6: =IF(Data!C99="","",Data!C99) -> Small | G6: =IF(Data!N99="","",Data!N99) -> 19 | H6: =IF(Data!O99="","",Data!O99) -> 6238B | I6: =IF(Data!M99="","",Data!M99) -> Terverifikasi — spek resmi
A7: SANY PALFINGER | B7: SANY PALFINGER SPK18500B | C7: =COUNTIFS(Data!$A$2:$A$765,$A7,Data!$B$2:$B$765,$B7) -> 3 | D7: =IF(Data!K454="","",Data!K454) -> 18.5 | E7: =IF(Data!L454="","",Data!L454) -> 19 | F7: =IF(Data!C454="","",Data!C454) -> Small | G7: =IF(Data!N454="","",Data!N454) -> 19 | H7: =IF(Data!O454="","",Data!O454) -> 6238B | I7: =IF(Data!M454="","",Data!M454) -> Terverifikasi — spek resmi
A8: SANY PALFINGER | B8: SANY PALFINGER SPK23500 | C8: =COUNTIFS(Data!$A$2:$A$765,$A8,Data!$B$2:$B$765,$B8) -> 42 | D8: =IF(Data!K103="","",Data!K103) -> 23 | E8: =IF(Data!L103="","",Data!L103) -> 23 | F8: =IF(Data!C103="","",Data!C103) -> Small | G8: =IF(Data!N103="","",Data!N103) -> 19 | H8: =IF(Data!O103="","",Data!O103) -> 9265C | I8: =IF(Data!M103="","",Data!M103) -> Terverifikasi — spek resmi
A9: SANY PALFINGER | B9: SANY PALFINGER SPK23500B | C9: =COUNTIFS(Data!$A$2:$A$765,$A9,Data!$B$2:$B$765,$B9) -> 28 | D9: =IF(Data!K145="","",Data!K145) -> 23 | E9: =IF(Data!L145="","",Data!L145) -> 23 | F9: =IF(Data!C145="","",Data!C145) -> Small | G9: =IF(Data!N145="","",Data!N145) -> 19 | H9: =IF(Data!O145="","",Data!O145) -> 9265C | I9: =IF(Data!M145="","",Data!M145) -> Terverifikasi — spek resmi
A10: SANY PALFINGER | B10: SANY PALFINGER SPK25000C | C10: =COUNTIFS(Data!$A$2:$A$765,$A10,Data!$B$2:$B$765,$B10) -> 1 | D10: =IF(Data!K169="","",Data!K169) -> 25 | E10: =IF(Data!L169="","",Data!L169) -> 25 | F10: =IF(Data!C169="","",Data!C169) -> Small | G10: =IF(Data!N169="","",Data!N169) -> 19 | H10: =IF(Data!O169="","",Data!O169) -> 730 | I10: =IF(Data!M169="","",Data!M169) -> Terverifikasi — spek resmi
A11: SANY PALFINGER | B11: SANY PALFINGER SPK32080 | C11: =COUNTIFS(Data!$A$2:$A$765,$A11,Data!$B$2:$B$765,$B11) -> 16 | D11: =IF(Data!K170="","",Data!K170) -> 30.4 | E11: =IF(Data!L170="","",Data!L170) -> 30 | F11: =IF(Data!C170="","",Data!C170) -> Medium | G11: =IF(Data!N170="","",Data!N170) -> 24 | H11: =IF(Data!O170="","",Data!O170) -> 734 | I11: =IF(Data!M170="","",Data!M170) -> Terverifikasi — spek resmi
A12: SANY PALFINGER | B12: SANY PALFINGER SPK32080B | C12: =COUNTIFS(Data!$A$2:$A$765,$A12,Data!$B$2:$B$765,$B12) -> 11 | D12: =IF(Data!K184="","",Data!K184) -> 30.4 | E12: =IF(Data!L184="","",Data!L184) -> 30 | F12: =IF(Data!C184="","",Data!C184) -> Medium | G12: =IF(Data!N184="","",Data!N184) -> 24 | H12: =IF(Data!O184="","",Data!O184) -> 734 | I12: =IF(Data!M184="","",Data!M184) -> Terverifikasi — spek resmi
A13: SANY PALFINGER | B13: SANY PALFINGER SPK32080C | C13: =COUNTIFS(Data!$A$2:$A$765,$A13,Data!$B$2:$B$765,$B13) -> 6 | D13: =IF(Data!K190="","",Data!K190) -> 30.4 | E13: =IF(Data!L190="","",Data!L190) -> 30 | F13: =IF(Data!C190="","",Data!C190) -> Medium | G13: =IF(Data!N190="","",Data!N190) -> 24 | H13: =IF(Data!O190="","",Data!O190) -> 734 | I13: =IF(Data!M190="","",Data!M190) -> Terverifikasi — spek resmi
A14: SANY PALFINGER | B14: SANY PALFINGER SPK36080 | C14: =COUNTIFS(Data!$A$2:$A$765,$A14,Data!$B$2:$B$765,$B14) -> 23 | D14: =IF(Data!K191="","",Data!K191) -> 36 | E14: =IF(Data!L191="","",Data!L191) -> 36 | F14: =IF(Data!C191="","",Data!C191) -> Medium | G14: =IF(Data!N191="","",Data!N191) -> 26 | H14: =IF(Data!O191="","",Data!O191) -> 9405C/9445C | I14: =IF(Data!M191="","",Data!M191) -> Terverifikasi — spek resmi
A15: SANY PALFINGER | B15: SANY PALFINGER SPK36080C | C15: =COUNTIFS(Data!$A$2:$A$765,$A15,Data!$B$2:$B$765,$B15) -> 11 | D15: =IF(Data!K208="","",Data!K208) -> 36 | E15: =IF(Data!L208="","",Data!L208) -> 36 | F15: =IF(Data!C208="","",Data!C208) -> Medium | G15: =IF(Data!N208="","",Data!N208) -> 26 | H15: =IF(Data!O208="","",Data!O208) -> 9405C/9445C | I15: =IF(Data!M208="","",Data!M208) -> Terverifikasi — spek resmi
A16: SANY PALFINGER | B16: SANY PALFINGER SPK38080 | C16: =COUNTIFS(Data!$A$2:$A$765,$A16,Data!$B$2:$B$765,$B16) -> 3 | D16: =IF(Data!K67="","",Data!K67) -> 38 | E16: =IF(Data!L67="","",Data!L67) -> 38 | F16: =IF(Data!C67="","",Data!C67) -> Medium | G16: =IF(Data!N67="","",Data!N67) -> 26 | H16: =IF(Data!O67="","",Data!O67) -> 746R | I16: =IF(Data!M67="","",Data!M67) -> Terverifikasi — spek resmi
A17: SANY PALFINGER | B17: SANY PALFINGER SPK42502 | C17: =COUNTIFS(Data!$A$2:$A$765,$A17,Data!$B$2:$B$765,$B17) -> 10 | D17: =IF(Data!K70="","",Data!K70) -> 42.5 | E17: =IF(Data!L70="","",Data!L70) -> 43 | F17: =IF(Data!C70="","",Data!C70) -> Medium | G17: =IF(Data!N70="","",Data!N70) -> 26 | H17: =IF(Data!O70="","",Data!O70) -> 746R | I17: =IF(Data!M70="","",Data!M70) -> Terverifikasi — spek resmi
A18: SANY PALFINGER | B18: SANY PALFINGER SPK42502C | C18: =COUNTIFS(Data!$A$2:$A$765,$A18,Data!$B$2:$B$765,$B18) -> 7 | D18: =IF(Data!K79="","",Data!K79) -> 42.5 | E18: =IF(Data!L79="","",Data!L79) -> 43 | F18: =IF(Data!C79="","",Data!C79) -> Medium | G18: =IF(Data!N79="","",Data!N79) -> 26 | H18: =IF(Data!O79="","",Data!O79) -> 746R | I18: =IF(Data!M79="","",Data!M79) -> Terverifikasi — spek resmi
A19: SANY PALFINGER | B19: SANY PALFINGER SPK42502E | C19: =COUNTIFS(Data!$A$2:$A$765,$A19,Data!$B$2:$B$765,$B19) -> 1 | D19: =IF(Data!K457="","",Data!K457) -> 42.5 | E19: =IF(Data!L457="","",Data!L457) -> 43 | F19: =IF(Data!C457="","",Data!C457) -> Medium | G19: =IF(Data!N457="","",Data!N457) -> 26 | H19: =IF(Data!O457="","",Data!O457) -> 746R | I19: =IF(Data!M457="","",Data!M457) -> Terverifikasi — spek resmi
A20: SANY PALFINGER | B20: SANY PALFINGER SPK61502 | C20: =COUNTIFS(Data!$A$2:$A$765,$A20,Data!$B$2:$B$765,$B20) -> 1 | D20: =IF(Data!K312="","",Data!K312) -> 61.5 | E20: =IF(Data!L312="","",Data!L312) -> 62 | F20: =IF(Data!C312="","",Data!C312) -> Heavy | G20: =IF(Data!N312="","",Data!N312) -> 42 | H20: =IF(Data!O312="","",Data!O312) -> 9661C | I20: =IF(Data!M312="","",Data!M312) -> Terverifikasi — spek resmi
A21: SANY PALFINGER | B21: SANY PALFINGER SPK6500 | C21: =COUNTIFS(Data!$A$2:$A$765,$A21,Data!$B$2:$B$765,$B21) -> 18 | D21: =IF(Data!K213="","",Data!K213) -> 6.5 | E21: =IF(Data!L213="","",Data!L213) -> 7 | F21: =IF(Data!C213="","",Data!C213) -> Light | G21: =IF(Data!N213="","",Data!N213) -> 10 | H21: =IF(Data!O213="","",Data!O213) -> 6108B | I21: =IF(Data!M213="","",Data!M213) -> Terverifikasi — spek resmi
A22: SANY PALFINGER | B22: SANY PALFINGER SPK6500A | C22: =COUNTIFS(Data!$A$2:$A$765,$A22,Data!$B$2:$B$765,$B22) -> 1 | D22: =IF(Data!K437="","",Data!K437) -> 6.5 | E22: =IF(Data!L437="","",Data!L437) -> 7 | F22: =IF(Data!C437="","",Data!C437) -> Light | G22: =IF(Data!N437="","",Data!N437) -> 10 | H22: =IF(Data!O437="","",Data!O437) -> 6108B | I22: =IF(Data!M437="","",Data!M437) -> Terverifikasi — spek resmi
A23: SANY PALFINGER | B23: SANY PALFINGER SPK8500 | C23: =COUNTIFS(Data!$A$2:$A$765,$A23,Data!$B$2:$B$765,$B23) -> 48 | D23: =IF(Data!K231="","",Data!K231) -> 8.2 | E23: =IF(Data!L231="","",Data!L231) -> 8 | F23: =IF(Data!C231="","",Data!C231) -> Light | G23: =IF(Data!N231="","",Data!N231) -> 10 | H23: =IF(Data!O231="","",Data!O231) -> 6108B | I23: =IF(Data!M231="","",Data!M231) -> Terverifikasi — spek resmi
A24: SANY PALFINGER | B24: SANY PALFINGER SPK8500A | C24: =COUNTIFS(Data!$A$2:$A$765,$A24,Data!$B$2:$B$765,$B24) -> 42 | D24: =IF(Data!K277="","",Data!K277) -> 8.2 | E24: =IF(Data!L277="","",Data!L277) -> 8 | F24: =IF(Data!C277="","",Data!C277) -> Light | G24: =IF(Data!N277="","",Data!N277) -> 10 | H24: =IF(Data!O277="","",Data!O277) -> 6108B | I24: =IF(Data!M277="","",Data!M277) -> Terverifikasi — spek resmi
A25: SANY PALFINGER | B25: SANY PALFINGER SPK8500B | C25: =COUNTIFS(Data!$A$2:$A$765,$A25,Data!$B$2:$B$765,$B25) -> 1 | D25: =IF(Data!K481="","",Data!K481) -> 8.2 | E25: =IF(Data!L481="","",Data!L481) -> 8 | F25: =IF(Data!C481="","",Data!C481) -> Light | G25: =IF(Data!N481="","",Data!N481) -> 10 | H25: =IF(Data!O481="","",Data!O481) -> 6108B | I25: =IF(Data!M481="","",Data!M481) -> Terverifikasi — spek resmi
A26: PALFINGER | B26: PALFINGER PK 15500 B | C26: =COUNTIFS(Data!$A$2:$A$765,$A26,Data!$B$2:$B$765,$B26) -> 6 | D26: =IF(Data!K655="","",Data!K655) -> 14.6 | E26: =IF(Data!L655="","",Data!L655) -> 15 | F26: =IF(Data!C655="","",Data!C655) -> Small | G26: =IF(Data!N655="","",Data!N655) -> 19 | H26: =IF(Data!O655="","",Data!O655) -> 6238B | I26: =IF(Data!M655="","",Data!M655) -> Terverifikasi — spek resmi
A27: PALFINGER | B27: PALFINGER PK 23500 C | C27: =COUNTIFS(Data!$A$2:$A$765,$A27,Data!$B$2:$B$765,$B27) -> 5 | D27: =IF(Data!K652="","",Data!K652) -> 23 | E27: =IF(Data!L652="","",Data!L652) -> 23 | F27: =IF(Data!C652="","",Data!C652) -> Small | G27: =IF(Data!N652="","",Data!N652) -> 19 | H27: =IF(Data!O652="","",Data!O652) -> 9265C | I27: =IF(Data!M652="","",Data!M652) -> Terverifikasi — spek resmi
A28: PALFINGER | B28: PALFINGER PK 23500 CR3X+RRC | C28: =COUNTIFS(Data!$A$2:$A$765,$A28,Data!$B$2:$B$765,$B28) -> 1 | D28: =IF(Data!K741="","",Data!K741) -> 23 | E28: =IF(Data!L741="","",Data!L741) -> 23 | F28: =IF(Data!C741="","",Data!C741) -> Small | G28: =IF(Data!N741="","",Data!N741) -> 19 | H28: =IF(Data!O741="","",Data!O741) -> 9265C | I28: =IF(Data!M741="","",Data!M741) -> Terverifikasi — spek resmi
A29: PALFINGER | B29: PALFINGER PK 32080 C | C29: =COUNTIFS(Data!$A$2:$A$765,$A29,Data!$B$2:$B$765,$B29) -> 8 | D29: =IF(Data!K666="","",Data!K666) -> 30.4 | E29: =IF(Data!L666="","",Data!L666) -> 30 | F29: =IF(Data!C666="","",Data!C666) -> Medium | G29: =IF(Data!N666="","",Data!N666) -> 24 | H29: =IF(Data!O666="","",Data!O666) -> 734 | I29: =IF(Data!M666="","",Data!M666) -> Terverifikasi — spek resmi
A30: PALFINGER | B30: PALFINGER PK 33002 | C30: =COUNTIFS(Data!$A$2:$A$765,$A30,Data!$B$2:$B$765,$B30) -> 1 | D30: =IF(Data!K64="","",Data!K64) -> 31.1 | E30: =IF(Data!L64="","",Data!L64) -> 31 | F30: =IF(Data!C64="","",Data!C64) -> Medium | G30: =IF(Data!N64="","",Data!N64) -> 24 | H30: =IF(Data!O64="","",Data!O64) -> 738R | I30: =IF(Data!M64="","",Data!M64) -> Terverifikasi — spek resmi
A31: PALFINGER | B31: PALFINGER PK 36050 | C31: =COUNTIFS(Data!$A$2:$A$765,$A31,Data!$B$2:$B$765,$B31) -> 1 | D31: =IF(Data!K62="","",Data!K62) -> 34.5 | E31: =IF(Data!L62="","",Data!L62) -> 35 | F31: =IF(Data!C62="","",Data!C62) -> Medium | G31: =IF(Data!N62="","",Data!N62) -> 26 | H31: =IF(Data!O62="","",Data!O62) -> 9405C/9445C | I31: =IF(Data!M62="","",Data!M62) -> Terverifikasi — spek resmi
A32: PALFINGER | B32: PALFINGER PK 41002 | C32: =COUNTIFS(Data!$A$2:$A$765,$A32,Data!$B$2:$B$765,$B32) -> 1 | D32: =IF(Data!K427="","",Data!K427) -> 38.4 | E32: =IF(Data!L427="","",Data!L427) -> 38 | F32: =IF(Data!C427="","",Data!C427) -> Medium | G32: =IF(Data!N427="","",Data!N427) -> 26 | H32: =IF(Data!O427="","",Data!O427) -> 746R | I32: =IF(Data!M427="","",Data!M427) -> Terverifikasi — spek resmi
A33: PALFINGER | B33: PALFINGER PK 41002 EH C | C33: =COUNTIFS(Data!$A$2:$A$765,$A33,Data!$B$2:$B$765,$B33) -> 12 | D33: =IF(Data!K703="","",Data!K703) -> 38.4 | E33: =IF(Data!L703="","",Data!L703) -> 38 | F33: =IF(Data!C703="","",Data!C703) -> Medium | G33: =IF(Data!N703="","",Data!N703) -> 26 | H33: =IF(Data!O703="","",Data!O703) -> 746R | I33: =IF(Data!M703="","",Data!M703) -> Terverifikasi — spek resmi
A34: PALFINGER | B34: PALFINGER PK 41002 MH C | C34: =COUNTIFS(Data!$A$2:$A$765,$A34,Data!$B$2:$B$765,$B34) -> 8 | D34: =IF(Data!K653="","",Data!K653) -> 38.4 | E34: =IF(Data!L653="","",Data!L653) -> 38 | F34: =IF(Data!C653="","",Data!C653) -> Medium | G34: =IF(Data!N653="","",Data!N653) -> 26 | H34: =IF(Data!O653="","",Data!O653) -> 746R | I34: =IF(Data!M653="","",Data!M653) -> Terverifikasi — spek resmi
A35: PALFINGER | B35: PALFINGER PK 48002 | C35: =COUNTIFS(Data!$A$2:$A$765,$A35,Data!$B$2:$B$765,$B35) -> 1 | D35: =IF(Data!K63="","",Data!K63) -> 46.5 | E35: =IF(Data!L63="","",Data!L63) -> 47 | F35: =IF(Data!C63="","",Data!C63) -> Heavy | G35: =IF(Data!N63="","",Data!N63) -> 42 | H35: =IF(Data!O63="","",Data!O63) -> 9601C | I35: =IF(Data!M63="","",Data!M63) -> Terverifikasi — spek resmi
A36: PALFINGER | B36: PALFINGER PK 5001 SLD 3 A | C36: =COUNTIFS(Data!$A$2:$A$765,$A36,Data!$B$2:$B$765,$B36) -> 3 | D36: =IF(Data!K647="","",Data!K647) -> 4.9 | E36: =IF(Data!L647="","",Data!L647) -> 5 | F36: =IF(Data!C647="","",Data!C647) -> Light | G36: =IF(Data!N647="","",Data!N647) -> 10 | H36: =IF(Data!O647="","",Data!O647) -> 6108B | I36: =IF(Data!M647="","",Data!M647) -> Terverifikasi — spek resmi
A37: PALFINGER | B37: PALFINGER PK 53002 SH B | C37: =COUNTIFS(Data!$A$2:$A$765,$A37,Data!$B$2:$B$765,$B37) -> 38 | D37: =IF(Data!K648="","",Data!K648) -> 50.1 | E37: =IF(Data!L648="","",Data!L648) -> 50 | F37: =IF(Data!C648="","",Data!C648) -> Heavy | G37: =IF(Data!N648="","",Data!N648) -> 42 | H37: =IF(Data!O648="","",Data!O648) -> 9601C | I37: =IF(Data!M648="","",Data!M648) -> Terverifikasi — spek resmi
A38: PALFINGER | B38: PALFINGER PK 53002 SH C | C38: =COUNTIFS(Data!$A$2:$A$765,$A38,Data!$B$2:$B$765,$B38) -> 1 | D38: =IF(Data!K710="","",Data!K710) -> 50.1 | E38: =IF(Data!L710="","",Data!L710) -> 50 | F38: =IF(Data!C710="","",Data!C710) -> Heavy | G38: =IF(Data!N710="","",Data!N710) -> 42 | H38: =IF(Data!O710="","",Data!O710) -> 9601C | I38: =IF(Data!M710="","",Data!M710) -> Terverifikasi — spek resmi
A39: PALFINGER | B39: PALFINGER PK 76002 EH D | C39: =COUNTIFS(Data!$A$2:$A$765,$A39,Data!$B$2:$B$765,$B39) -> 2 | D39: =IF(Data!K682="","",Data!K682) -> 71.6 | E39: =IF(Data!L682="","",Data!L682) -> 72 | F39: =IF(Data!C682="","",Data!C682) -> Heavy | G39: =IF(Data!N682="","",Data!N682) -> 42 | H39: =IF(Data!O682="","",Data!O682) -> 990R | I39: =IF(Data!M682="","",Data!M682) -> Terverifikasi — spek resmi
A40: PALFINGER | B40: PALFINGER PK 8500 | C40: =COUNTIFS(Data!$A$2:$A$765,$A40,Data!$B$2:$B$765,$B40) -> 1 | D40: =IF(Data!K441="","",Data!K441) -> 7.6 | E40: =IF(Data!L441="","",Data!L441) -> 8 | F40: =IF(Data!C441="","",Data!C441) -> Light | G40: =IF(Data!N441="","",Data!N441) -> 10 | H40: =IF(Data!O441="","",Data!O441) -> 6108B | I40: =IF(Data!M441="","",Data!M441) -> Terverifikasi — catatan klasifikasi
A41: PALFINGER | B41: PALFINGER PK 8501 SLD 3 A | C41: =COUNTIFS(Data!$A$2:$A$765,$A41,Data!$B$2:$B$765,$B41) -> 34 | D41: =IF(Data!K650="","",Data!K650) -> 8.2 | E41: =IF(Data!L650="","",Data!L650) -> 8 | F41: =IF(Data!C650="","",Data!C650) -> Light | G41: =IF(Data!N650="","",Data!N650) -> 10 | H41: =IF(Data!O650="","",Data!O650) -> 6108B | I41: =IF(Data!M650="","",Data!M650) -> Terverifikasi — spek resmi
...

Sheet 7. Raw Data
A1: RAW DATA — 764 TRANSAKSI KNUCKLE BOOM (AUDITED)
A2: Brand | B2: Model | C2: Kategori Max Lifting Moment | D2: Year | E2: Date | F2: Unit Price (USD) | G2: Importer | H2: Description | I2: Rentang Kategori | J2: Source | K2: Max Lifting Moment asli (tm) | L2: Max Lifting Moment dibulatkan (tm) | M2: Status Verifikasi | N2: GVW Rekomendasi (ton) | O2: Model Ferrari Acuan | P2: Basis Pairing (tm)
A3: =IF(Data!A2="","",Data!A2) -> BOB-LIFT | B3: =IF(Data!B2="","",Data!B2) -> BOB-LIFT GKB3.2ZA2 | C3: =IF(Data!C2="","",Data!C2) -> Light | D3: =IF(Data!D2="","",Data!D2) -> 2025 | E3: =IF(Data!E2="","",Data!E2) -> 45864 | F3: =IF(Data!F2="","",Data!F2) -> 7899.59 | G3: =IF(Data!G2="","",Data!G2) -> PT INDOTARA PERSADA | H3: =IF(Data!H2="","",Data!H2) -> KNUCKLE BOOM CRANE GKB3.2ZA2 - 3.2 TON | ... P3: =IF(Data!P2="","",Data!P2) -> 7
A4: =IF(Data!A3="","",Data!A3) -> BOB-LIFT | B4: =IF(Data!B3="","",Data!B3) -> BOB-LIFT GKB5ZA2 | C4: =IF(Data!C3="","",Data!C3) -> Small | D4: =IF(Data!D3="","",Data!D3) -> 2025 | E4: =IF(Data!E3="","",Data!E3) -> 45864 | F4: =IF(Data!F3="","",Data!F3) -> 9630.03 | G4: =IF(Data!G3="","",Data!G3) -> PT INDOTARA PERSADA | H4: =IF(Data!H3="","",Data!H3) -> KNUCKLE BOOM CRANE GKB5ZA2 - 5 TON | ... P4: =IF(Data!P3="","",Data!P3) -> 10
A5: =IF(Data!A4="","",Data!A4) -> BOB-LIFT | B5: =IF(Data!B4="","",Data!B4) -> BOB-LIFT Q5ZA2 | C5: =IF(Data!C4="","",Data!C4) -> Small | D5: =IF(Data!D4="","",Data!D4) -> 2023 | E5: =IF(Data!E4="","",Data!E4) | F5: =IF(Data!F4="","",Data!F4) -> 12350 | G5: =IF(Data!G4="","",Data!G4) -> BUMI MINERAL SULAWESI | H5: =IF(Data!H4="","",Data!H4) -> 5 TON KNUCKLE BOOM CRANE Q5ZA2 | ... P5: =IF(Data!P4="","",Data!P4) -> 11
A6: =IF(Data!A5="","",Data!A5) -> BOB-LIFT | B6: =IF(Data!B5="","",Data!B5) -> BOB-LIFT Q5ZA2 | C6: =IF(Data!C5="","",Data!C5) -> Small | D6: =IF(Data!D5="","",Data!D5) -> 2023 | E6: =IF(Data!E5="","",Data!E5) | F6: =IF(Data!F5="","",Data!F5) -> 13000 | G6: =IF(Data!G5="","",Data!G5) -> PT TRICONVILLE INDONESIA | H6: =IF(Data!H5="","",Data!H5) -> Q5ZA2 5 TONS KNUCKLE BOOM CRANE | ... P6: =IF(Data!P5="","",Data!P5) -> 11
A7: =IF(Data!A6="","",Data!A6) -> BOB-LIFT | B7: =IF(Data!B6="","",Data!B6) -> BOB-LIFT GKB08ZA3T | C7: =IF(Data!C6="","",Data!C6) -> Light | D7: =IF(Data!D6="","",Data!D6) -> 2025 | E7: =IF(Data!E6="","",Data!E6) -> 45864 | F7: =IF(Data!F6="","",Data!F6) -> 2984.26 | G7: =IF(Data!G6="","",Data!G6) -> PT INDOTARA PERSADA | H7: =IF(Data!H6="","",Data!H6) -> KNUCKLE BOOM CRANE GKB08ZA3T 0.8 TON | ... P7: =IF(Data!P6="","",Data!P6) -> 1
A8: =IF(Data!A7="","",Data!A7) -> FASSI | B8: =IF(Data!B7="","",Data!B7) -> FASSI F85B.0.22 | C8: =IF(Data!C7="","",Data!C7) -> Small | D8: =IF(Data!D7="","",Data!D7) -> 2025 | E8: =IF(Data!E7="","",Data!E7) -> 45864 | F8: =IF(Data!F7="","",Data!F7) -> 18850 | G8: =IF(Data!G7="","",Data!G7) -> PT FORESTA TRANSTEK | H8: =IF(Data!H7="","",Data!H7) -> NEW UNIT FASSI F85B.0.22 HYDRAULIC CRANE, SERIAL NO: 0850-2457 | ... P8: =IF(Data!P7="","",Data!P7) -> 9
A9: =IF(Data!A8="","",Data!A8) -> FASSI | B9: =IF(Data!B8="","",Data!B8) -> FASSI F215A.2.24 | C9: =IF(Data!C8="","",Data!C8) -> Small | D9: =IF(Data!D8="","",Data!D8) -> 2025 | E9: =IF(Data!E8="","",Data!E8) -> 45772 | F9: =IF(Data!F8="","",Data!F8) -> 32296.18 | G9: =IF(Data!G8="","",Data!G8) -> PT BUMI MAKMUR TRANSPERKASA | H9: =IF(Data!H8="","",Data!H8) -> NEW FASSI HYDRAULIC CRANE C/W MOUNTING KIT AND PUMP F215A.2.24 | ... P9: =IF(Data!P8="","",Data!P8) -> 20
